{
  "metadata": {
    "language_info": {
      "codemirror_mode": {
        "name": "python",
        "version": 3
      },
      "file_extension": ".py",
      "mimetype": "text/x-python",
      "name": "python",
      "nbconvert_exporter": "python",
      "pygments_lexer": "ipython3",
      "version": "3.8"
    },
    "kernelspec": {
      "name": "python",
      "display_name": "Python (Pyodide)",
      "language": "python"
    }
  },
  "nbformat_minor": 4,
  "nbformat": 4,
  "cells": [
    {
      "cell_type": "markdown",
      "source": "Q1.An exception is an event, which occurs during the execution of a program that disrupts the normal flow of the program's instructions.",
      "metadata": {}
    },
    {
      "cell_type": "markdown",
      "source": "Syntax Errors:\n    When the proper syntax of the language is not followed then a syntax error is thrown.",
      "metadata": {}
    },
    {
      "cell_type": "code",
      "source": "amount = 10000\nif(amount>2999)\n\tprint(\"You are eligible to purchase Dsa Self Paced\")\n\t\n",
      "metadata": {
        "trusted": true
      },
      "execution_count": 1,
      "outputs": [
        {
          "ename": "<class 'SyntaxError'>",
          "evalue": "expected ':' (<ipython-input-1-73c3de38eeb8>, line 2)",
          "traceback": [
            "\u001b[0;36m  Cell \u001b[0;32mIn[1], line 2\u001b[0;36m\u001b[0m\n\u001b[0;31m    if(amount>2999)\u001b[0m\n\u001b[0m                   ^\u001b[0m\n\u001b[0;31mSyntaxError\u001b[0m\u001b[0;31m:\u001b[0m expected ':'\n"
          ],
          "output_type": "error"
        }
      ]
    },
    {
      "cell_type": "markdown",
      "source": "Logical Error:\n    When in the runtime an error that occurs after passing the syntax test is called exception or logical type",
      "metadata": {}
    },
    {
      "cell_type": "code",
      "source": "marks = 10000\na = marks / 0\nprint(a)\n",
      "metadata": {
        "trusted": true
      },
      "execution_count": 2,
      "outputs": [
        {
          "ename": "<class 'ZeroDivisionError'>",
          "evalue": "division by zero",
          "traceback": [
            "\u001b[0;31m---------------------------------------------------------------------------\u001b[0m",
            "\u001b[0;31mZeroDivisionError\u001b[0m                         Traceback (most recent call last)",
            "Cell \u001b[0;32mIn[2], line 2\u001b[0m\n\u001b[1;32m      1\u001b[0m marks \u001b[38;5;241m=\u001b[39m \u001b[38;5;241m10000\u001b[39m\n\u001b[0;32m----> 2\u001b[0m a \u001b[38;5;241m=\u001b[39m \u001b[43mmarks\u001b[49m\u001b[43m \u001b[49m\u001b[38;5;241;43m/\u001b[39;49m\u001b[43m \u001b[49m\u001b[38;5;241;43m0\u001b[39;49m\n\u001b[1;32m      3\u001b[0m \u001b[38;5;28mprint\u001b[39m(a)\n",
            "\u001b[0;31mZeroDivisionError\u001b[0m: division by zero"
          ],
          "output_type": "error"
        }
      ]
    },
    {
      "cell_type": "markdown",
      "source": "Q2. when the exception not handled, the code which present below the logical error will not be executed",
      "metadata": {}
    },
    {
      "cell_type": "code",
      "source": "f=open(\"test.txt\",'r')\nprint(\"hi\")",
      "metadata": {
        "trusted": true
      },
      "execution_count": 3,
      "outputs": [
        {
          "ename": "<class 'FileNotFoundError'>",
          "evalue": "[Errno 44] No such file or directory: 'test.txt'",
          "traceback": [
            "\u001b[0;31m---------------------------------------------------------------------------\u001b[0m",
            "\u001b[0;31mFileNotFoundError\u001b[0m                         Traceback (most recent call last)",
            "Cell \u001b[0;32mIn[3], line 1\u001b[0m\n\u001b[0;32m----> 1\u001b[0m f\u001b[38;5;241m=\u001b[39m\u001b[38;5;28;43mopen\u001b[39;49m\u001b[43m(\u001b[49m\u001b[38;5;124;43m\"\u001b[39;49m\u001b[38;5;124;43mtest.txt\u001b[39;49m\u001b[38;5;124;43m\"\u001b[39;49m\u001b[43m,\u001b[49m\u001b[38;5;124;43m'\u001b[39;49m\u001b[38;5;124;43mr\u001b[39;49m\u001b[38;5;124;43m'\u001b[39;49m\u001b[43m)\u001b[49m\n\u001b[1;32m      2\u001b[0m \u001b[38;5;28mprint\u001b[39m(\u001b[38;5;124m\"\u001b[39m\u001b[38;5;124mhi\u001b[39m\u001b[38;5;124m\"\u001b[39m)\n",
            "File \u001b[0;32m/lib/python3.11/site-packages/IPython/core/interactiveshell.py:284\u001b[0m, in \u001b[0;36m_modified_open\u001b[0;34m(file, *args, **kwargs)\u001b[0m\n\u001b[1;32m    277\u001b[0m \u001b[38;5;28;01mif\u001b[39;00m file \u001b[38;5;129;01min\u001b[39;00m {\u001b[38;5;241m0\u001b[39m, \u001b[38;5;241m1\u001b[39m, \u001b[38;5;241m2\u001b[39m}:\n\u001b[1;32m    278\u001b[0m     \u001b[38;5;28;01mraise\u001b[39;00m \u001b[38;5;167;01mValueError\u001b[39;00m(\n\u001b[1;32m    279\u001b[0m         \u001b[38;5;124mf\u001b[39m\u001b[38;5;124m\"\u001b[39m\u001b[38;5;124mIPython won\u001b[39m\u001b[38;5;124m'\u001b[39m\u001b[38;5;124mt let you open fd=\u001b[39m\u001b[38;5;132;01m{\u001b[39;00mfile\u001b[38;5;132;01m}\u001b[39;00m\u001b[38;5;124m by default \u001b[39m\u001b[38;5;124m\"\u001b[39m\n\u001b[1;32m    280\u001b[0m         \u001b[38;5;124m\"\u001b[39m\u001b[38;5;124mas it is likely to crash IPython. If you know what you are doing, \u001b[39m\u001b[38;5;124m\"\u001b[39m\n\u001b[1;32m    281\u001b[0m         \u001b[38;5;124m\"\u001b[39m\u001b[38;5;124myou can use builtins\u001b[39m\u001b[38;5;124m'\u001b[39m\u001b[38;5;124m open.\u001b[39m\u001b[38;5;124m\"\u001b[39m\n\u001b[1;32m    282\u001b[0m     )\n\u001b[0;32m--> 284\u001b[0m \u001b[38;5;28;01mreturn\u001b[39;00m \u001b[43mio_open\u001b[49m\u001b[43m(\u001b[49m\u001b[43mfile\u001b[49m\u001b[43m,\u001b[49m\u001b[43m \u001b[49m\u001b[38;5;241;43m*\u001b[39;49m\u001b[43margs\u001b[49m\u001b[43m,\u001b[49m\u001b[43m \u001b[49m\u001b[38;5;241;43m*\u001b[39;49m\u001b[38;5;241;43m*\u001b[39;49m\u001b[43mkwargs\u001b[49m\u001b[43m)\u001b[49m\n",
            "\u001b[0;31mFileNotFoundError\u001b[0m: [Errno 44] No such file or directory: 'test.txt'"
          ],
          "output_type": "error"
        }
      ]
    },
    {
      "cell_type": "code",
      "source": "try:\n    f=open(\"test.txt\",'r')\nexcept Exception as e:\n    print(\"unable to open the file,file not exists\")",
      "metadata": {
        "trusted": true
      },
      "execution_count": 4,
      "outputs": [
        {
          "name": "stdout",
          "text": "unable to open the file,file not exists\n",
          "output_type": "stream"
        }
      ]
    },
    {
      "cell_type": "markdown",
      "source": "In the above program , print statement not executed because of opening a file which doesn't exists.Then handling the exception works, even if file not exists.",
      "metadata": {}
    },
    {
      "cell_type": "markdown",
      "source": "Q3.Try and except used to handle the exception.",
      "metadata": {}
    },
    {
      "cell_type": "code",
      "source": "try:\n    f=open(\"file.txt\",'w')\n    f.write(\"this is my file\")\nexcept Exception as e:\n    print(\"file writing not successful\")\nelse:\n    f.close()",
      "metadata": {
        "trusted": true
      },
      "execution_count": 5,
      "outputs": []
    },
    {
      "cell_type": "markdown",
      "source": "Q4. \n1.Try and else.\nIn the above try and else program. The else block will be executed atlast after try and exception block",
      "metadata": {}
    },
    {
      "cell_type": "code",
      "source": "#2.Finally\n\ntry:\n    f=open(\"file1.txt\",'r')\n    f.read()\nfinally:\n    print(\"this block will be executed though try block has ended up with error\")",
      "metadata": {
        "trusted": true
      },
      "execution_count": 6,
      "outputs": [
        {
          "name": "stdout",
          "text": "this block will be executed though try block has ended up with error\n",
          "output_type": "stream"
        },
        {
          "ename": "<class 'FileNotFoundError'>",
          "evalue": "[Errno 44] No such file or directory: 'file1.txt'",
          "traceback": [
            "\u001b[0;31m---------------------------------------------------------------------------\u001b[0m",
            "\u001b[0;31mFileNotFoundError\u001b[0m                         Traceback (most recent call last)",
            "Cell \u001b[0;32mIn[6], line 4\u001b[0m\n\u001b[1;32m      1\u001b[0m \u001b[38;5;66;03m#2.Finally\u001b[39;00m\n\u001b[1;32m      3\u001b[0m \u001b[38;5;28;01mtry\u001b[39;00m:\n\u001b[0;32m----> 4\u001b[0m     f\u001b[38;5;241m=\u001b[39m\u001b[38;5;28;43mopen\u001b[39;49m\u001b[43m(\u001b[49m\u001b[38;5;124;43m\"\u001b[39;49m\u001b[38;5;124;43mfile1.txt\u001b[39;49m\u001b[38;5;124;43m\"\u001b[39;49m\u001b[43m,\u001b[49m\u001b[38;5;124;43m'\u001b[39;49m\u001b[38;5;124;43mr\u001b[39;49m\u001b[38;5;124;43m'\u001b[39;49m\u001b[43m)\u001b[49m\n\u001b[1;32m      5\u001b[0m     f\u001b[38;5;241m.\u001b[39mread()\n\u001b[1;32m      6\u001b[0m \u001b[38;5;28;01mfinally\u001b[39;00m:\n",
            "File \u001b[0;32m/lib/python3.11/site-packages/IPython/core/interactiveshell.py:284\u001b[0m, in \u001b[0;36m_modified_open\u001b[0;34m(file, *args, **kwargs)\u001b[0m\n\u001b[1;32m    277\u001b[0m \u001b[38;5;28;01mif\u001b[39;00m file \u001b[38;5;129;01min\u001b[39;00m {\u001b[38;5;241m0\u001b[39m, \u001b[38;5;241m1\u001b[39m, \u001b[38;5;241m2\u001b[39m}:\n\u001b[1;32m    278\u001b[0m     \u001b[38;5;28;01mraise\u001b[39;00m \u001b[38;5;167;01mValueError\u001b[39;00m(\n\u001b[1;32m    279\u001b[0m         \u001b[38;5;124mf\u001b[39m\u001b[38;5;124m\"\u001b[39m\u001b[38;5;124mIPython won\u001b[39m\u001b[38;5;124m'\u001b[39m\u001b[38;5;124mt let you open fd=\u001b[39m\u001b[38;5;132;01m{\u001b[39;00mfile\u001b[38;5;132;01m}\u001b[39;00m\u001b[38;5;124m by default \u001b[39m\u001b[38;5;124m\"\u001b[39m\n\u001b[1;32m    280\u001b[0m         \u001b[38;5;124m\"\u001b[39m\u001b[38;5;124mas it is likely to crash IPython. If you know what you are doing, \u001b[39m\u001b[38;5;124m\"\u001b[39m\n\u001b[1;32m    281\u001b[0m         \u001b[38;5;124m\"\u001b[39m\u001b[38;5;124myou can use builtins\u001b[39m\u001b[38;5;124m'\u001b[39m\u001b[38;5;124m open.\u001b[39m\u001b[38;5;124m\"\u001b[39m\n\u001b[1;32m    282\u001b[0m     )\n\u001b[0;32m--> 284\u001b[0m \u001b[38;5;28;01mreturn\u001b[39;00m \u001b[43mio_open\u001b[49m\u001b[43m(\u001b[49m\u001b[43mfile\u001b[49m\u001b[43m,\u001b[49m\u001b[43m \u001b[49m\u001b[38;5;241;43m*\u001b[39;49m\u001b[43margs\u001b[49m\u001b[43m,\u001b[49m\u001b[43m \u001b[49m\u001b[38;5;241;43m*\u001b[39;49m\u001b[38;5;241;43m*\u001b[39;49m\u001b[43mkwargs\u001b[49m\u001b[43m)\u001b[49m\n",
            "\u001b[0;31mFileNotFoundError\u001b[0m: [Errno 44] No such file or directory: 'file1.txt'"
          ],
          "output_type": "error"
        }
      ]
    },
    {
      "cell_type": "markdown",
      "source": "3.raise is used for exception handling.",
      "metadata": {}
    },
    {
      "cell_type": "code",
      "source": "x = \"hello\"\n\nif not type(x) is int:\n  raise TypeError(\"Only integers are allowed\")",
      "metadata": {
        "trusted": true
      },
      "execution_count": 7,
      "outputs": [
        {
          "ename": "<class 'TypeError'>",
          "evalue": "Only integers are allowed",
          "traceback": [
            "\u001b[0;31m---------------------------------------------------------------------------\u001b[0m",
            "\u001b[0;31mTypeError\u001b[0m                                 Traceback (most recent call last)",
            "Cell \u001b[0;32mIn[7], line 4\u001b[0m\n\u001b[1;32m      1\u001b[0m x \u001b[38;5;241m=\u001b[39m \u001b[38;5;124m\"\u001b[39m\u001b[38;5;124mhello\u001b[39m\u001b[38;5;124m\"\u001b[39m\n\u001b[1;32m      3\u001b[0m \u001b[38;5;28;01mif\u001b[39;00m \u001b[38;5;129;01mnot\u001b[39;00m \u001b[38;5;28mtype\u001b[39m(x) \u001b[38;5;129;01mis\u001b[39;00m \u001b[38;5;28mint\u001b[39m:\n\u001b[0;32m----> 4\u001b[0m   \u001b[38;5;28;01mraise\u001b[39;00m \u001b[38;5;167;01mTypeError\u001b[39;00m(\u001b[38;5;124m\"\u001b[39m\u001b[38;5;124mOnly integers are allowed\u001b[39m\u001b[38;5;124m\"\u001b[39m)\n",
            "\u001b[0;31mTypeError\u001b[0m: Only integers are allowed"
          ],
          "output_type": "error"
        }
      ]
    },
    {
      "cell_type": "markdown",
      "source": "Q5.Custom exception are user-defined exception.If we don't want to use built-in exception, then we can define our own exception statement by inherting the exception in class.",
      "metadata": {}
    },
    {
      "cell_type": "code",
      "source": "# define Python user-defined exceptions\nclass InvalidAgeException(Exception):\n    \"Raised when the input value is less than 18\"\n    pass\n\n# you need to guess this number\nnumber = 18\n\ntry:\n    input_num = int(input(\"Enter a number: \"))\n    if input_num < number:\n        raise InvalidAgeException\n    else:\n        print(\"Eligible to Vote\")\n        \nexcept InvalidAgeException:\n    print(\"Exception occurred: Invalid Age\")",
      "metadata": {
        "trusted": true
      },
      "execution_count": 8,
      "outputs": [
        {
          "ename": "<class 'TypeError'>",
          "evalue": "'<' not supported between instances of 'PyodideFuture' and 'int'",
          "traceback": [
            "\u001b[0;31m---------------------------------------------------------------------------\u001b[0m",
            "\u001b[0;31mTypeError\u001b[0m                                 Traceback (most recent call last)",
            "Cell \u001b[0;32mIn[8], line 11\u001b[0m\n\u001b[1;32m      9\u001b[0m \u001b[38;5;28;01mtry\u001b[39;00m:\n\u001b[1;32m     10\u001b[0m     input_num \u001b[38;5;241m=\u001b[39m \u001b[38;5;28minput\u001b[39m(\u001b[38;5;124m\"\u001b[39m\u001b[38;5;124mEnter a number: \u001b[39m\u001b[38;5;124m\"\u001b[39m)\n\u001b[0;32m---> 11\u001b[0m     \u001b[38;5;28;01mif\u001b[39;00m \u001b[43minput_num\u001b[49m\u001b[43m \u001b[49m\u001b[38;5;241;43m<\u001b[39;49m\u001b[43m \u001b[49m\u001b[43mnumber\u001b[49m:\n\u001b[1;32m     12\u001b[0m         \u001b[38;5;28;01mraise\u001b[39;00m InvalidAgeException\n\u001b[1;32m     13\u001b[0m     \u001b[38;5;28;01melse\u001b[39;00m:\n",
            "\u001b[0;31mTypeError\u001b[0m: '<' not supported between instances of 'PyodideFuture' and 'int'"
          ],
          "output_type": "error"
        },
        {
          "output_type": "stream",
          "name": "stdin",
          "text": "Enter a number:  5\n"
        }
      ]
    },
    {
      "cell_type": "code",
      "source": "",
      "metadata": {},
      "execution_count": null,
      "outputs": []
    }
  ]
}